<sdf version='1.7'>
  <world name='lake'>
    <physics name='default_physics' default='1' type='ode'>
      <max_step_size>0.002</max_step_size>
      <real_time_factor>1</real_time_factor>
      <real_time_update_rate>500</real_time_update_rate>
      <ode>
        <solver>
          <type>quick</type>
          <iters>50</iters>
          <sor>0.5</sor>
          <use_dynamic_moi_rescaling>0</use_dynamic_moi_rescaling>
        </solver>
        <constraints>
          <cfm>0</cfm>
          <erp>0.2</erp>
          <contact_max_correcting_vel>100</contact_max_correcting_vel>
          <contact_surface_layer>0.001</contact_surface_layer>
        </constraints>
      </ode>
    </physics>
    <scene>
      <ambient>0.01 0.01 0.01 1</ambient>
      <sky>
        <clouds>
          <speed>12</speed>
        </clouds>
      </sky>
      <shadows>0</shadows>
      <background>0.7 0.7 0.7 1</background>
    </scene>
    <spherical_coordinates>
      <latitude_deg>47.6279</latitude_deg>
      <longitude_deg>9.33455</longitude_deg>
      <surface_model>EARTH_WGS84</surface_model>
      <elevation>0</elevation>
      <heading_deg>0</heading_deg>
    </spherical_coordinates>
    <light name='sun1' type='directional'>
      <pose>50 0 150 0 -0 0</pose>
      <diffuse>1 1 1 1</diffuse>
      <specular>0.1 0.1 0.1 1</specular>
      <direction>0.3 0.3 -1</direction>
      <cast_shadows>0</cast_shadows>
      <attenuation>
        <range>10</range>
      </attenuation>
      <spot>
        <inner_angle>0</inner_angle>
        <outer_angle>0</outer_angle>
        <falloff>0</falloff>
      </spot>
    </light>
    <light name='sun' type='directional'>
      <cast_shadows>0</cast_shadows>
      <pose>0 0 10 0 -0 0</pose>
      <diffuse>0.8 0.8 0.8 1</diffuse>
      <specular>0.2 0.2 0.2 1</specular>
      <attenuation>
        <range>1000</range>
        <constant>0.9</constant>
        <linear>0.01</linear>
        <quadratic>0.001</quadratic>
      </attenuation>
      <direction>-0.5 0.1 -0.9</direction>
      <spot>
        <inner_angle>0</inner_angle>
        <outer_angle>0</outer_angle>
        <falloff>0</falloff>
      </spot>
    </light>
    <model name='world_ned'>
      <pose>0 0 0 0 -0 0</pose>
      <static>1</static>
      <link name='world_ned'>
        <gravity>0</gravity>
        <pose>0 0 0 -3.14159 -0 1.5708</pose>
        <visual name='N_visual'>
          <pose>0.25 0 0 1.5708 -0 1.5708</pose>
          <geometry>
            <cylinder>
              <radius>0.01</radius>
              <length>0.5</length>
            </cylinder>
          </geometry>
          <material>
            <script>
              <uri>file://media/materials/scripts/gazebo.material</uri>
              <name>Gazebo/Red</name>
            </script>
          </material>
        </visual>
        <visual name='E_visual'>
          <pose>0 0.25 0 1.5708 -0 0</pose>
          <geometry>
            <cylinder>
              <radius>0.01</radius>
              <length>0.5</length>
            </cylinder>
          </geometry>
          <material>
            <script>
              <uri>file://media/materials/scripts/gazebo.material</uri>
              <name>Gazebo/Green</name>
            </script>
          </material>
        </visual>
        <visual name='D_visual'>
          <pose>0 0 0.25 0 -0 0</pose>
          <geometry>
            <cylinder>
              <radius>0.01</radius>
              <length>0.5</length>
            </cylinder>
          </geometry>
          <material>
            <script>
              <uri>file://media/materials/scripts/gazebo.material</uri>
              <name>Gazebo/Blue</name>
            </script>
          </material>
        </visual>
        <self_collide>0</self_collide>
        <enable_wind>0</enable_wind>
        <kinematic>0</kinematic>
      </link>
    </model>
    <model name='lake'>
      <static>1</static>
      <link name='lake_link'>
        <visual name='lake_bottom'>
          <cast_shadows>0</cast_shadows>
          <pose>0 0 0 0 -0 0</pose>
          <geometry>
            <mesh>
              <uri>model://lake/meshes/LakeBottom.dae</uri>
              <scale>1 1 1</scale>
            </mesh>
          </geometry>
          <material>
            <script>
              <uri>file://Media/materials/scripts/sand.material</uri>
              <name>UUVSimulator/SandAndStones</name>
            </script>
          </material>
        </visual>
        <collision name='lake_bottom'>
          <pose>0 0 0 0 -0 0</pose>
          <geometry>
            <mesh>
              <uri>model://lake/meshes/LakeBottom.dae</uri>
              <scale>1 1 1</scale>
            </mesh>
          </geometry>
          <max_contacts>10</max_contacts>
          <surface>
            <contact>
              <ode/>
            </contact>
            <bounce/>
            <friction>
              <torsional>
                <ode/>
              </torsional>
              <ode/>
            </friction>
          </surface>
        </collision>
        <visual name='surface'>
          <pose>0 0 0 0 -0 0</pose>
          <geometry>
            <mesh>
              <uri>model://lake/meshes/WaterSurface.dae</uri>
              <scale>1 1 1</scale>
            </mesh>
          </geometry>
          <material>
            <script>
              <uri>file://Media/materials/scripts/water.material</uri>
              <name>UUVSimulator/StaticTurquoiseWater</name>
            </script>
          </material>
        </visual>
        <self_collide>0</self_collide>
        <enable_wind>0</enable_wind>
        <kinematic>0</kinematic>
      </link>
      <pose>0 0 0 0 -0 0</pose>
    </model>
    <plugin name='underwater_current_plugin' filename='libuuv_underwater_current_ros_plugin.so'>
      <namespace>hydrodynamics</namespace>
      <constant_current>
        <topic>current_velocity</topic>
        <velocity>
          <mean>0</mean>
          <min>0</min>
          <max>5</max>
          <mu>0.0</mu>
          <noiseAmp>0.0</noiseAmp>
        </velocity>
        <horizontal_angle>
          <mean>0</mean>
          <min>-3.141592653589793238</min>
          <max>3.141592653589793238</max>
          <mu>0.0</mu>
          <noiseAmp>0.0</noiseAmp>
        </horizontal_angle>
        <vertical_angle>
          <mean>0</mean>
          <min>-3.141592653589793238</min>
          <max>3.141592653589793238</max>
          <mu>0.0</mu>
          <noiseAmp>0.0</noiseAmp>
        </vertical_angle>
      </constant_current>
    </plugin>
    <plugin name='sc_interface' filename='libuuv_sc_ros_interface_plugin.so'/>
    <gravity>0 0 -9.8</gravity>
    <magnetic_field>6e-06 2.3e-05 -4.2e-05</magnetic_field>
    <atmosphere type='adiabatic'/>
    <wind/>
    <state world_name='lake'>
      <sim_time>723 286000000</sim_time>
      <real_time>170 158728677</real_time>
      <wall_time>1653761809 676298620</wall_time>
      <iterations>84822</iterations>
      <model name='gate'>
        <pose>3.01586 -2.06417 -1.64571 0 -0 1.56898</pose>
        <scale>1 1 1</scale>
        <link name='link'>
          <pose>3.01586 -2.06417 -1.64571 0 -0 1.56898</pose>
          <velocity>0 0 0 0 -0 0</velocity>
          <acceleration>0 0 0 0 -0 0</acceleration>
          <wrench>0 0 0 0 -0 0</wrench>
        </link>
      </model>
      <model name='gman_torpedo'>
        <pose>2.977 -0.004194 -0.241483 0 0 -1.58169</pose>
        <scale>1 1 1</scale>
        <link name='link'>
          <pose>2.977 -0.004194 -0.241483 0 0 -1.58169</pose>
          <velocity>0 0 0 0 -0 0</velocity>
          <acceleration>0 0 0 0 -0 0</acceleration>
          <wrench>0 0 0 0 -0 0</wrench>
        </link>
      </model>
      <model name='lake'>
        <pose>0 0 0 0 -0 0</pose>
        <scale>1 1 1</scale>
        <link name='lake_link'>
          <pose>0 0 0 0 -0 0</pose>
          <velocity>0 0 0 0 -0 0</velocity>
          <acceleration>0 0 0 0 -0 0</acceleration>
          <wrench>0 0 0 0 -0 0</wrench>
        </link>
      </model>
      <model name='pole'>
        <pose>4.98558 -0.029448 -0.617743 0 -0 0</pose>
        <scale>1 1 1</scale>
        <link name='link'>
          <pose>4.98558 -0.029448 -0.617743 0 -0 0</pose>
          <velocity>0 0 0 0 -0 0</velocity>
          <acceleration>0 0 0 0 -0 0</acceleration>
          <wrench>0 0 0 0 -0 0</wrench>
        </link>
      </model>
      <model name='tempest'>
        <pose>-0 -0 -0.179985 1e-05 2e-06 0</pose>
        <scale>1 1 1</scale>
        <link name='tempest/base_link'>
          <pose>-0 -0 -0.179985 1e-05 2e-06 0</pose>
          <velocity>0 -0 0 0 -0 0</velocity>
          <acceleration>0 0 0 -0 -0 -0</acceleration>
          <wrench>0 0 0 0 -0 0</wrench>
        </link>
        <link name='tempest/dvl_link'>
          <pose>0.011 -0.001998 -0.349985 6e-06 8e-06 -0.785398</pose>
          <velocity>0 0 0 0 -0 0</velocity>
          <acceleration>0 0 -0 0 -0 0</acceleration>
          <wrench>0 0 -0 0 -0 0</wrench>
        </link>
        <link name='tempest/imu_revolute_link'>
          <pose>0.07 -0.127001 -0.075986 -1.57431 0.005098 3.14159</pose>
          <velocity>-0 -0 -0 0 -0 0</velocity>
          <acceleration>0 0 -0 0 -0 0</acceleration>
          <wrench>0 0 -0 0 -0 0</wrench>
        </link>
        <link name='tempest/pose_sensor_link'>
          <pose>-0 -0 -0.179985 1e-05 2e-06 0</pose>
          <velocity>0 0 0 0 -0 0</velocity>
          <acceleration>0 0 -0 0 -0 0</acceleration>
          <wrench>0 0 -0 0 -0 0</wrench>
        </link>
        <link name='tempest/pressure_link'>
          <pose>-0.141 0.136999 -0.121183 1e-05 2e-06 0</pose>
          <velocity>-0 0 0 0 -0 0</velocity>
          <acceleration>-0 0 -0 0 -0 0</acceleration>
          <wrench>-0 0 -0 0 -0 0</wrench>
        </link>
        <link name='tempest/stereo/imu_revolute_link'>
          <pose>0.144 -0.129001 -0.095987 1.5708 1e-05 -1.5708</pose>
          <velocity>-0 0 0 0 -0 0</velocity>
          <acceleration>0 0 -0 0 -0 0</acceleration>
          <wrench>0 0 -0 0 -0 0</wrench>
        </link>
        <link name='tempest/thruster_0'>
          <pose>0.405 -0.403001 -0.10799 1.15748 1.57079 1.15748</pose>
          <velocity>-0 0 0 -0 -0 -0</velocity>
          <acceleration>-0 0 -0 -0 -0 -0</acceleration>
          <wrench>-0 0 -0 0 -0 0</wrench>
        </link>
        <link name='tempest/thruster_1'>
          <pose>-0.378 -0.403001 -0.107988 1.15748 1.57079 1.15748</pose>
          <velocity>-0 -0 0 -0 -0 -0</velocity>
          <acceleration>-0 -0 -0 -0 -0 -0</acceleration>
          <wrench>-0 -0 -0 0 -0 0</wrench>
        </link>
        <link name='tempest/thruster_2'>
          <pose>-0.378 0.410999 -0.10798 1.15748 1.57079 1.15748</pose>
          <velocity>-0 -0 -0 -0 -0 -0</velocity>
          <acceleration>-0 -0 -0 -0 -0 -0</acceleration>
          <wrench>-0 -0 -0 0 -0 0</wrench>
        </link>
        <link name='tempest/thruster_3'>
          <pose>0.405 0.410999 -0.107982 1.15748 1.57079 1.15748</pose>
          <velocity>-0 0 -0 -0 -0 -0</velocity>
          <acceleration>-0 0 -0 -0 -0 -0</acceleration>
          <wrench>-0 0 -0 0 -0 0</wrench>
        </link>
        <link name='tempest/thruster_4'>
          <pose>0.346 -0.344001 -0.100589 -8e-06 6e-06 -2.35619</pose>
          <velocity>-0 0 0 0 -0 0</velocity>
          <acceleration>-0 0 -0 0 -0 0</acceleration>
          <wrench>-0 0 -0 0 -0 0</wrench>
        </link>
        <link name='tempest/thruster_5'>
          <pose>-0.29 -0.344001 -0.100588 6e-06 8e-06 -0.7854</pose>
          <velocity>-0 0 0 0 -0 0</velocity>
          <acceleration>-0 0 -0 -0 -0 -0</acceleration>
          <wrench>-0 0 -0 0 -0 0</wrench>
        </link>
        <link name='tempest/thruster_6'>
          <pose>-0.29 0.321999 -0.100581 8e-06 -6e-06 0.7854</pose>
          <velocity>-0 0 0 0 -0 0</velocity>
          <acceleration>-0 0 -0 0 -0 0</acceleration>
          <wrench>-0 0 -0 0 -0 0</wrench>
        </link>
        <link name='tempest/thruster_7'>
          <pose>0.346 0.321999 -0.100582 -6e-06 -8e-06 2.35619</pose>
          <velocity>-0 0 -0 0 -0 0</velocity>
          <acceleration>-0 0 -0 0 -0 0</acceleration>
          <wrench>-0 0 -0 0 -0 0</wrench>
        </link>
      </model>
      <model name='world_ned'>
        <pose>0 0 0 0 -0 0</pose>
        <scale>1 1 1</scale>
        <link name='world_ned'>
          <pose>0 0 0 -3.14159 -0 1.5708</pose>
          <velocity>0 0 0 0 -0 0</velocity>
          <acceleration>0 0 0 0 -0 0</acceleration>
          <wrench>0 0 0 0 -0 0</wrench>
        </link>
      </model>
      <light name='sun'>
        <pose>0 0 10 0 -0 0</pose>
      </light>
      <light name='sun1'>
        <pose>50 0 150 0 -0 0</pose>
      </light>
    </state>
    <gui fullscreen='0'>
      <camera name='user_camera'>
        <pose>-2.29696 4.11964 4.08614 -0 0.617797 -0.815839</pose>
        <view_controller>orbit</view_controller>
        <projection_type>perspective</projection_type>
      </camera>
    </gui>
    <model name='tempest'>
      <link name='tempest/base_link'>
        <inertial>
          <pose>0.01381 0.00911 0.0319 0 -0 0</pose>
          <mass>30.9804</mass>
          <inertia>
            <ixx>1.32001</ixx>
            <ixy>2.0616e-06</ixy>
            <ixz>-7.51384e-07</ixz>
            <iyy>2.84001</iyy>
            <iyz>7.81166e-07</iyz>
            <izz>3.65001</izz>
          </inertia>
        </inertial>
        <collision name='tempest/base_link_fixed_joint_lump__tempest/origin_collision'>
          <pose>0.386 -0.352 0.15 0 -0 0</pose>
          <geometry>
            <mesh>
              <scale>1 1 1</scale>
              <uri>/home/brach/osu-uwrt/riptide_software_old/src/riptide_descriptions/meshes/Tempest.dae</uri>
            </mesh>
          </geometry>
          <max_contacts>10</max_contacts>
          <surface>
            <contact>
              <ode/>
            </contact>
            <bounce/>
            <friction>
              <torsional>
                <ode/>
              </torsional>
              <ode/>
            </friction>
          </surface>
        </collision>
        <collision name='tempest/base_link_fixed_joint_lump__tempest/stereo/base_link_collision_1'>
          <pose>0.144 -0.069 0.084 3.14159 1.57079 3.14159</pose>
          <geometry>
            <cylinder>
              <length>1e-06</length>
              <radius>1e-06</radius>
            </cylinder>
          </geometry>
          <max_contacts>10</max_contacts>
          <surface>
            <contact>
              <ode/>
            </contact>
            <bounce/>
            <friction>
              <torsional>
                <ode/>
              </torsional>
              <ode/>
            </friction>
          </surface>
        </collision>
        <collision name='tempest/base_link_fixed_joint_lump__tempest/stereo/left_link_collision_2'>
          <pose>0.144 -0.069 0.084 3.14159 1.57079 3.14159</pose>
          <geometry>
            <cylinder>
              <length>1e-06</length>
              <radius>1e-06</radius>
            </cylinder>
          </geometry>
          <surface>
            <contact>
              <ode/>
            </contact>
            <friction>
              <ode/>
              <torsional>
                <ode/>
              </torsional>
            </friction>
            <bounce/>
          </surface>
          <max_contacts>10</max_contacts>
        </collision>
        <collision name='tempest/base_link_fixed_joint_lump__tempest/stereo/right_link_collision_3'>
          <pose>0.144 -0.189 0.084 3.14159 1.57079 3.14159</pose>
          <geometry>
            <cylinder>
              <length>1e-06</length>
              <radius>1e-06</radius>
            </cylinder>
          </geometry>
          <surface>
            <contact>
              <ode/>
            </contact>
            <friction>
              <ode/>
              <torsional>
                <ode/>
              </torsional>
            </friction>
            <bounce/>
          </surface>
          <max_contacts>10</max_contacts>
        </collision>
        <visual name='tempest/base_link_fixed_joint_lump__tempest/origin_visual'>
          <pose>0.386 -0.352 0.15 0 -0 0</pose>
          <geometry>
            <mesh>
              <scale>1 1 1</scale>
              <uri>/home/brach/osu-uwrt/riptide_software_old/src/riptide_descriptions/meshes/Tempest.dae</uri>
            </mesh>
          </geometry>
        </visual>
        <sensor name='stereo/left' type='camera'>
          <camera>
            <horizontal_fov>1.418</horizontal_fov>
            <image>
              <width>1280</width>
              <height>720</height>
              <format>R8G8B8</format>
            </image>
            <clip>
              <near>0.05</near>
              <far>3000</far>
            </clip>
            <noise>
              <type>gaussian</type>
              <mean>0</mean>
              <stddev>0.02</stddev>
            </noise>
          </camera>
          <plugin name='stereo/left_controller' filename='libgazebo_ros_camera.so'>
            <alwaysOn>1</alwaysOn>
            <updateRate>60</updateRate>
            <cameraName>stereo/left</cameraName>
            <imageTopicName>image_raw</imageTopicName>
            <cameraInfoTopicName>camera_info</cameraInfoTopicName>
            <frameName>tempest/stereo/left_optical</frameName>
            <hackBaseline>0.12</hackBaseline>
            <robotNamespace>/tempest/</robotNamespace>
          </plugin>
          <always_on>1</always_on>
          <update_rate>60</update_rate>
          <pose>0.144 -0.069 0.084 0 -0 0</pose>
        </sensor>
        <sensor name='stereo/right' type='camera'>
          <camera>
            <horizontal_fov>1.418</horizontal_fov>
            <image>
              <width>1280</width>
              <height>720</height>
              <format>R8G8B8</format>
            </image>
            <clip>
              <near>0.05</near>
              <far>3000</far>
            </clip>
            <noise>
              <type>gaussian</type>
              <mean>0</mean>
              <stddev>0.02</stddev>
            </noise>
          </camera>
          <plugin name='stereo/right_controller' filename='libgazebo_ros_camera.so'>
            <alwaysOn>1</alwaysOn>
            <updateRate>60</updateRate>
            <cameraName>stereo/right</cameraName>
            <imageTopicName>image_raw</imageTopicName>
            <cameraInfoTopicName>camera_info</cameraInfoTopicName>
            <frameName>tempest/stereo/right_optical</frameName>
            <hackBaseline>0.12</hackBaseline>
            <robotNamespace>/tempest/</robotNamespace>
          </plugin>
          <always_on>1</always_on>
          <update_rate>60</update_rate>
          <pose>0.144 -0.189 0.084 0 -0 0</pose>
        </sensor>
        <self_collide>0</self_collide>
        <enable_wind>0</enable_wind>
        <kinematic>0</kinematic>
      </link>
      <joint name='tempest/dvl_joint' type='revolute'>
        <pose relative_to='tempest/base_link'>0.011 -0.002 -0.17 0 0 -0.785398</pose>
        <parent>tempest/base_link</parent>
        <child>tempest/dvl_link</child>
        <axis>
          <xyz>1 0 0</xyz>
          <limit>
            <lower>0</lower>
            <upper>0</upper>
            <effort>0</effort>
            <velocity>0</velocity>
          </limit>
          <dynamics>
            <spring_reference>0</spring_reference>
            <spring_stiffness>0</spring_stiffness>
          </dynamics>
        </axis>
      </joint>
      <link name='tempest/dvl_link'>
        <pose relative_to='tempest/dvl_joint'>0 0 0 0 -0 0</pose>
        <inertial>
          <pose>0 0 0 0 -0 0</pose>
          <mass>5e-05</mass>
          <inertia>
            <ixx>5e-06</ixx>
            <ixy>0</ixy>
            <ixz>7.48675e-23</ixz>
            <iyy>5e-06</iyy>
            <iyz>0</iyz>
            <izz>5e-06</izz>
          </inertia>
        </inertial>
        <collision name='tempest/dvl_link_collision'>
          <pose>0 0 0 3.14159 1.57079 3.14159</pose>
          <geometry>
            <cylinder>
              <length>1e-06</length>
              <radius>1e-06</radius>
            </cylinder>
          </geometry>
          <max_contacts>10</max_contacts>
          <surface>
            <contact>
              <ode/>
            </contact>
            <bounce/>
            <friction>
              <torsional>
                <ode/>
              </torsional>
              <ode/>
            </friction>
          </surface>
        </collision>
        <collision name='tempest/dvl_link_fixed_joint_lump__tempest/dvl_sonar0_link_collision_1'>
          <pose>0 0 0 -3.14159 0.261796 2.35619</pose>
          <geometry>
            <cylinder>
              <length>1e-06</length>
              <radius>1e-06</radius>
            </cylinder>
          </geometry>
          <surface>
            <contact>
              <ode/>
            </contact>
            <friction>
              <ode/>
              <torsional>
                <ode/>
              </torsional>
            </friction>
            <bounce/>
          </surface>
          <max_contacts>10</max_contacts>
        </collision>
        <collision name='tempest/dvl_link_fixed_joint_lump__tempest/dvl_sonar1_link_collision_2'>
          <pose>0 0 0 3.14159 0.261796 0.785403</pose>
          <geometry>
            <cylinder>
              <length>1e-06</length>
              <radius>1e-06</radius>
            </cylinder>
          </geometry>
          <surface>
            <contact>
              <ode/>
            </contact>
            <friction>
              <ode/>
              <torsional>
                <ode/>
              </torsional>
            </friction>
            <bounce/>
          </surface>
          <max_contacts>10</max_contacts>
        </collision>
        <collision name='tempest/dvl_link_fixed_joint_lump__tempest/dvl_sonar2_link_collision_3'>
          <pose>0 0 0 -3.14159 0.261796 -0.785403</pose>
          <geometry>
            <cylinder>
              <length>1e-06</length>
              <radius>1e-06</radius>
            </cylinder>
          </geometry>
          <surface>
            <contact>
              <ode/>
            </contact>
            <friction>
              <ode/>
              <torsional>
                <ode/>
              </torsional>
            </friction>
            <bounce/>
          </surface>
          <max_contacts>10</max_contacts>
        </collision>
        <collision name='tempest/dvl_link_fixed_joint_lump__tempest/dvl_sonar3_link_collision_4'>
          <pose>0 0 0 3.14159 0.261796 -2.35619</pose>
          <geometry>
            <cylinder>
              <length>1e-06</length>
              <radius>1e-06</radius>
            </cylinder>
          </geometry>
          <surface>
            <contact>
              <ode/>
            </contact>
            <friction>
              <ode/>
              <torsional>
                <ode/>
              </torsional>
            </friction>
            <bounce/>
          </surface>
          <max_contacts>10</max_contacts>
        </collision>
        <sensor name='dvl_sonar0' type='ray'>
          <update_rate>8</update_rate>
          <visualize>0</visualize>
          <ray>
            <scan>
              <horizontal>
                <samples>3</samples>
                <resolution>1</resolution>
                <min_angle>-0.03</min_angle>
                <max_angle>0.03</max_angle>
              </horizontal>
              <vertical>
                <samples>3</samples>
                <resolution>1</resolution>
                <min_angle>-0.03</min_angle>
                <max_angle>0.03</max_angle>
              </vertical>
            </scan>
            <range>
              <min>0.55</min>
              <max>10</max>
              <resolution>0.01</resolution>
            </range>
          </ray>
          <plugin name='dvl_sonar0' filename='libgazebo_ros_range.so'>
            <gaussianNoise>0.005</gaussianNoise>
            <alwaysOn>1</alwaysOn>
            <updateRate>8</updateRate>
            <topicName>dvl_sonar0</topicName>
            <frameName>tempest/dvl_sonar0_link</frameName>
            <fov>0.06</fov>
            <radiation>ultrasound</radiation>
            <robotNamespace>/tempest/</robotNamespace>
          </plugin>
          <pose>0 0 0 -0 1.309 -0.7854</pose>
        </sensor>
        <sensor name='dvl_sonar1' type='ray'>
          <update_rate>8</update_rate>
          <visualize>0</visualize>
          <ray>
            <scan>
              <horizontal>
                <samples>3</samples>
                <resolution>1</resolution>
                <min_angle>-0.03</min_angle>
                <max_angle>0.03</max_angle>
              </horizontal>
              <vertical>
                <samples>3</samples>
                <resolution>1</resolution>
                <min_angle>-0.03</min_angle>
                <max_angle>0.03</max_angle>
              </vertical>
            </scan>
            <range>
              <min>0.55</min>
              <max>10</max>
              <resolution>0.01</resolution>
            </range>
          </ray>
          <plugin name='dvl_sonar1' filename='libgazebo_ros_range.so'>
            <gaussianNoise>0.005</gaussianNoise>
            <alwaysOn>1</alwaysOn>
            <updateRate>8</updateRate>
            <topicName>dvl_sonar1</topicName>
            <frameName>tempest/dvl_sonar1_link</frameName>
            <fov>0.06</fov>
            <radiation>ultrasound</radiation>
            <robotNamespace>/tempest/</robotNamespace>
          </plugin>
          <pose>0 0 0 0 1.309 -2.35619</pose>
        </sensor>
        <sensor name='dvl_sonar2' type='ray'>
          <update_rate>8</update_rate>
          <visualize>0</visualize>
          <ray>
            <scan>
              <horizontal>
                <samples>3</samples>
                <resolution>1</resolution>
                <min_angle>-0.03</min_angle>
                <max_angle>0.03</max_angle>
              </horizontal>
              <vertical>
                <samples>3</samples>
                <resolution>1</resolution>
                <min_angle>-0.03</min_angle>
                <max_angle>0.03</max_angle>
              </vertical>
            </scan>
            <range>
              <min>0.55</min>
              <max>10</max>
              <resolution>0.01</resolution>
            </range>
          </ray>
          <plugin name='dvl_sonar2' filename='libgazebo_ros_range.so'>
            <gaussianNoise>0.005</gaussianNoise>
            <alwaysOn>1</alwaysOn>
            <updateRate>8</updateRate>
            <topicName>dvl_sonar2</topicName>
            <frameName>tempest/dvl_sonar2_link</frameName>
            <fov>0.06</fov>
            <radiation>ultrasound</radiation>
            <robotNamespace>/tempest/</robotNamespace>
          </plugin>
          <pose>0 0 0 -0 1.309 2.35619</pose>
        </sensor>
        <sensor name='dvl_sonar3' type='ray'>
          <update_rate>8</update_rate>
          <visualize>0</visualize>
          <ray>
            <scan>
              <horizontal>
                <samples>3</samples>
                <resolution>1</resolution>
                <min_angle>-0.03</min_angle>
                <max_angle>0.03</max_angle>
              </horizontal>
              <vertical>
                <samples>3</samples>
                <resolution>1</resolution>
                <min_angle>-0.03</min_angle>
                <max_angle>0.03</max_angle>
              </vertical>
            </scan>
            <range>
              <min>0.55</min>
              <max>10</max>
              <resolution>0.01</resolution>
            </range>
          </ray>
          <plugin name='dvl_sonar3' filename='libgazebo_ros_range.so'>
            <gaussianNoise>0.005</gaussianNoise>
            <alwaysOn>1</alwaysOn>
            <updateRate>8</updateRate>
            <topicName>dvl_sonar3</topicName>
            <frameName>tempest/dvl_sonar3_link</frameName>
            <fov>0.06</fov>
            <radiation>ultrasound</radiation>
            <robotNamespace>/tempest/</robotNamespace>
          </plugin>
          <pose>0 0 0 0 1.309 0.7854</pose>
        </sensor>
        <self_collide>0</self_collide>
        <enable_wind>0</enable_wind>
        <kinematic>0</kinematic>
      </link>
      <joint name='tempest/imu_revolute_joint' type='revolute'>
        <pose relative_to='tempest/base_link'>0.07 -0.127 0.104 -1.5743 0.0051 3.14159</pose>
        <parent>tempest/base_link</parent>
        <child>tempest/imu_revolute_link</child>
        <axis>
          <xyz>1 0 0</xyz>
          <limit>
            <lower>0</lower>
            <upper>0</upper>
            <effort>0</effort>
            <velocity>0</velocity>
          </limit>
          <dynamics>
            <spring_reference>0</spring_reference>
            <spring_stiffness>0</spring_stiffness>
          </dynamics>
        </axis>
      </joint>
      <link name='tempest/imu_revolute_link'>
        <pose relative_to='tempest/imu_revolute_joint'>0 0 0 0 -0 0</pose>
        <inertial>
          <pose>0 0 0 0 -0 0</pose>
          <mass>1e-05</mass>
          <inertia>
            <ixx>1e-06</ixx>
            <ixy>0</ixy>
            <ixz>0</ixz>
            <iyy>1e-06</iyy>
            <iyz>0</iyz>
            <izz>1e-06</izz>
          </inertia>
        </inertial>
        <self_collide>0</self_collide>
        <enable_wind>0</enable_wind>
        <kinematic>0</kinematic>
      </link>
      <joint name='tempest/pressure_joint' type='revolute'>
        <pose relative_to='tempest/base_link'>-0.141 0.137 0.0588 0 -0 0</pose>
        <parent>tempest/base_link</parent>
        <child>tempest/pressure_link</child>
        <axis>
          <xyz>1 0 0</xyz>
          <limit>
            <lower>0</lower>
            <upper>0</upper>
            <effort>0</effort>
            <velocity>0</velocity>
          </limit>
          <dynamics>
            <spring_reference>0</spring_reference>
            <spring_stiffness>0</spring_stiffness>
          </dynamics>
        </axis>
      </joint>
      <link name='tempest/pressure_link'>
        <pose relative_to='tempest/pressure_joint'>0 0 0 0 -0 0</pose>
        <inertial>
          <pose>0 0 0 0 -0 0</pose>
          <mass>1e-05</mass>
          <inertia>
            <ixx>1e-06</ixx>
            <ixy>0</ixy>
            <ixz>0</ixz>
            <iyy>1e-06</iyy>
            <iyz>0</iyz>
            <izz>1e-06</izz>
          </inertia>
        </inertial>
        <collision name='tempest/pressure_link_collision'>
          <pose>0 0 0 3.14159 1.57079 3.14159</pose>
          <geometry>
            <cylinder>
              <length>1e-06</length>
              <radius>1e-06</radius>
            </cylinder>
          </geometry>
          <max_contacts>10</max_contacts>
          <surface>
            <contact>
              <ode/>
            </contact>
            <bounce/>
            <friction>
              <torsional>
                <ode/>
              </torsional>
              <ode/>
            </friction>
          </surface>
        </collision>
        <self_collide>0</self_collide>
        <enable_wind>0</enable_wind>
        <kinematic>0</kinematic>
      </link>
      <joint name='tempest/stereo/imu_revolute_joint' type='revolute'>
        <pose relative_to='tempest/base_link'>0.144 -0.129 0.084 1.5708 0 -1.5708</pose>
        <parent>tempest/base_link</parent>
        <child>tempest/stereo/imu_revolute_link</child>
        <axis>
          <xyz>1 0 0</xyz>
          <limit>
            <lower>0</lower>
            <upper>0</upper>
            <effort>0</effort>
            <velocity>0</velocity>
          </limit>
          <dynamics>
            <spring_reference>0</spring_reference>
            <spring_stiffness>0</spring_stiffness>
          </dynamics>
        </axis>
      </joint>
      <link name='tempest/stereo/imu_revolute_link'>
        <pose relative_to='tempest/stereo/imu_revolute_joint'>0 0 0 0 -0 0</pose>
        <inertial>
          <pose>0 0 0 0 -0 0</pose>
          <mass>1e-05</mass>
          <inertia>
            <ixx>1e-06</ixx>
            <ixy>0</ixy>
            <ixz>0</ixz>
            <iyy>1e-06</iyy>
            <iyz>0</iyz>
            <izz>1e-06</izz>
          </inertia>
        </inertial>
        <self_collide>0</self_collide>
        <enable_wind>0</enable_wind>
        <kinematic>0</kinematic>
      </link>
      <joint name='tempest/thruster_0_joint' type='revolute'>
        <pose relative_to='tempest/base_link'>0.405 -0.403 0.072 0 1.57079 0</pose>
        <parent>tempest/base_link</parent>
        <child>tempest/thruster_0</child>
        <axis>
          <xyz>1 0 0</xyz>
          <limit>
            <lower>-1e+16</lower>
            <upper>1e+16</upper>
          </limit>
          <dynamics>
            <spring_reference>0</spring_reference>
            <spring_stiffness>0</spring_stiffness>
          </dynamics>
        </axis>
      </joint>
      <link name='tempest/thruster_0'>
        <pose relative_to='tempest/thruster_0_joint'>0 0 0 0 -0 0</pose>
        <inertial>
          <pose>0 0 0 0 -0 0</pose>
          <mass>1e-05</mass>
          <inertia>
            <ixx>1e-06</ixx>
            <ixy>0</ixy>
            <ixz>0</ixz>
            <iyy>1e-06</iyy>
            <iyz>0</iyz>
            <izz>1e-06</izz>
          </inertia>
        </inertial>
        <collision name='tempest/thruster_0_collision'>
          <pose>0 0 0 3.14159 1.57079 3.14159</pose>
          <geometry>
            <cylinder>
              <length>1e-06</length>
              <radius>1e-06</radius>
            </cylinder>
          </geometry>
          <surface>
            <contact>
              <ode/>
            </contact>
            <friction>
              <ode/>
              <torsional>
                <ode/>
              </torsional>
            </friction>
            <bounce/>
          </surface>
          <max_contacts>10</max_contacts>
        </collision>
        <visual name='tempest/thruster_0_visual'>
          <pose>0 0 0 0 -0 0</pose>
          <geometry>
            <mesh>
              <scale>1 1 1</scale>
              <uri>/home/brach/osu-uwrt/riptide_software_old/src/riptide_descriptions/meshes/Propeller.dae</uri>
            </mesh>
          </geometry>
        </visual>
        <self_collide>0</self_collide>
        <enable_wind>0</enable_wind>
        <kinematic>0</kinematic>
      </link>
      <joint name='tempest/thruster_1_joint' type='revolute'>
        <pose relative_to='tempest/base_link'>-0.378 -0.403 0.072 0 1.57079 0</pose>
        <parent>tempest/base_link</parent>
        <child>tempest/thruster_1</child>
        <axis>
          <xyz>1 0 0</xyz>
          <limit>
            <lower>-1e+16</lower>
            <upper>1e+16</upper>
          </limit>
          <dynamics>
            <spring_reference>0</spring_reference>
            <spring_stiffness>0</spring_stiffness>
          </dynamics>
        </axis>
      </joint>
      <link name='tempest/thruster_1'>
        <pose relative_to='tempest/thruster_1_joint'>0 0 0 0 -0 0</pose>
        <inertial>
          <pose>0 0 0 0 -0 0</pose>
          <mass>1e-05</mass>
          <inertia>
            <ixx>1e-06</ixx>
            <ixy>0</ixy>
            <ixz>0</ixz>
            <iyy>1e-06</iyy>
            <iyz>0</iyz>
            <izz>1e-06</izz>
          </inertia>
        </inertial>
        <collision name='tempest/thruster_1_collision'>
          <pose>0 0 0 3.14159 1.57079 3.14159</pose>
          <geometry>
            <cylinder>
              <length>1e-06</length>
              <radius>1e-06</radius>
            </cylinder>
          </geometry>
          <surface>
            <contact>
              <ode/>
            </contact>
            <friction>
              <ode/>
              <torsional>
                <ode/>
              </torsional>
            </friction>
            <bounce/>
          </surface>
          <max_contacts>10</max_contacts>
        </collision>
        <visual name='tempest/thruster_1_visual'>
          <pose>0 0 0 0 -0 0</pose>
          <geometry>
            <mesh>
              <scale>1 1 1</scale>
              <uri>/home/brach/osu-uwrt/riptide_software_old/src/riptide_descriptions/meshes/Propeller.dae</uri>
            </mesh>
          </geometry>
        </visual>
        <self_collide>0</self_collide>
        <enable_wind>0</enable_wind>
        <kinematic>0</kinematic>
      </link>
      <joint name='tempest/thruster_2_joint' type='revolute'>
        <pose relative_to='tempest/base_link'>-0.378 0.411 0.072 0 1.57079 0</pose>
        <parent>tempest/base_link</parent>
        <child>tempest/thruster_2</child>
        <axis>
          <xyz>1 0 0</xyz>
          <limit>
            <lower>-1e+16</lower>
            <upper>1e+16</upper>
          </limit>
          <dynamics>
            <spring_reference>0</spring_reference>
            <spring_stiffness>0</spring_stiffness>
          </dynamics>
        </axis>
      </joint>
      <link name='tempest/thruster_2'>
        <pose relative_to='tempest/thruster_2_joint'>0 0 0 0 -0 0</pose>
        <inertial>
          <pose>0 0 0 0 -0 0</pose>
          <mass>1e-05</mass>
          <inertia>
            <ixx>1e-06</ixx>
            <ixy>0</ixy>
            <ixz>0</ixz>
            <iyy>1e-06</iyy>
            <iyz>0</iyz>
            <izz>1e-06</izz>
          </inertia>
        </inertial>
        <collision name='tempest/thruster_2_collision'>
          <pose>0 0 0 3.14159 1.57079 3.14159</pose>
          <geometry>
            <cylinder>
              <length>1e-06</length>
              <radius>1e-06</radius>
            </cylinder>
          </geometry>
          <surface>
            <contact>
              <ode/>
            </contact>
            <friction>
              <ode/>
              <torsional>
                <ode/>
              </torsional>
            </friction>
            <bounce/>
          </surface>
          <max_contacts>10</max_contacts>
        </collision>
        <visual name='tempest/thruster_2_visual'>
          <pose>0 0 0 0 -0 0</pose>
          <geometry>
            <mesh>
              <scale>1 1 1</scale>
              <uri>/home/brach/osu-uwrt/riptide_software_old/src/riptide_descriptions/meshes/Propeller.dae</uri>
            </mesh>
          </geometry>
        </visual>
        <self_collide>0</self_collide>
        <enable_wind>0</enable_wind>
        <kinematic>0</kinematic>
      </link>
      <joint name='tempest/thruster_3_joint' type='revolute'>
        <pose relative_to='tempest/base_link'>0.405 0.411 0.072 0 1.57079 0</pose>
        <parent>tempest/base_link</parent>
        <child>tempest/thruster_3</child>
        <axis>
          <xyz>1 0 0</xyz>
          <limit>
            <lower>-1e+16</lower>
            <upper>1e+16</upper>
          </limit>
          <dynamics>
            <spring_reference>0</spring_reference>
            <spring_stiffness>0</spring_stiffness>
          </dynamics>
        </axis>
      </joint>
      <link name='tempest/thruster_3'>
        <pose relative_to='tempest/thruster_3_joint'>0 0 0 0 -0 0</pose>
        <inertial>
          <pose>0 0 0 0 -0 0</pose>
          <mass>1e-05</mass>
          <inertia>
            <ixx>1e-06</ixx>
            <ixy>0</ixy>
            <ixz>0</ixz>
            <iyy>1e-06</iyy>
            <iyz>0</iyz>
            <izz>1e-06</izz>
          </inertia>
        </inertial>
        <collision name='tempest/thruster_3_collision'>
          <pose>0 0 0 3.14159 1.57079 3.14159</pose>
          <geometry>
            <cylinder>
              <length>1e-06</length>
              <radius>1e-06</radius>
            </cylinder>
          </geometry>
          <surface>
            <contact>
              <ode/>
            </contact>
            <friction>
              <ode/>
              <torsional>
                <ode/>
              </torsional>
            </friction>
            <bounce/>
          </surface>
          <max_contacts>10</max_contacts>
        </collision>
        <visual name='tempest/thruster_3_visual'>
          <pose>0 0 0 0 -0 0</pose>
          <geometry>
            <mesh>
              <scale>1 1 1</scale>
              <uri>/home/brach/osu-uwrt/riptide_software_old/src/riptide_descriptions/meshes/Propeller.dae</uri>
            </mesh>
          </geometry>
        </visual>
        <self_collide>0</self_collide>
        <enable_wind>0</enable_wind>
        <kinematic>0</kinematic>
      </link>
      <joint name='tempest/thruster_4_joint' type='revolute'>
        <pose relative_to='tempest/base_link'>0.346 -0.344 0.0794 0 0 -2.35619</pose>
        <parent>tempest/base_link</parent>
        <child>tempest/thruster_4</child>
        <axis>
          <xyz>1 0 0</xyz>
          <limit>
            <lower>-1e+16</lower>
            <upper>1e+16</upper>
          </limit>
          <dynamics>
            <spring_reference>0</spring_reference>
            <spring_stiffness>0</spring_stiffness>
          </dynamics>
        </axis>
      </joint>
      <link name='tempest/thruster_4'>
        <pose relative_to='tempest/thruster_4_joint'>0 0 0 0 -0 0</pose>
        <inertial>
          <pose>0 0 0 0 -0 0</pose>
          <mass>1e-05</mass>
          <inertia>
            <ixx>1e-06</ixx>
            <ixy>0</ixy>
            <ixz>0</ixz>
            <iyy>1e-06</iyy>
            <iyz>0</iyz>
            <izz>1e-06</izz>
          </inertia>
        </inertial>
        <collision name='tempest/thruster_4_collision'>
          <pose>0 0 0 3.14159 1.57079 3.14159</pose>
          <geometry>
            <cylinder>
              <length>1e-06</length>
              <radius>1e-06</radius>
            </cylinder>
          </geometry>
          <surface>
            <contact>
              <ode/>
            </contact>
            <friction>
              <ode/>
              <torsional>
                <ode/>
              </torsional>
            </friction>
            <bounce/>
          </surface>
          <max_contacts>10</max_contacts>
        </collision>
        <visual name='tempest/thruster_4_visual'>
          <pose>0 0 0 0 -0 0</pose>
          <geometry>
            <mesh>
              <scale>1 1 1</scale>
              <uri>/home/brach/osu-uwrt/riptide_software_old/src/riptide_descriptions/meshes/Propeller.dae</uri>
            </mesh>
          </geometry>
        </visual>
        <self_collide>0</self_collide>
        <enable_wind>0</enable_wind>
        <kinematic>0</kinematic>
      </link>
      <joint name='tempest/thruster_5_joint' type='revolute'>
        <pose relative_to='tempest/base_link'>-0.29 -0.344 0.0794 0 0 -0.7854</pose>
        <parent>tempest/base_link</parent>
        <child>tempest/thruster_5</child>
        <axis>
          <xyz>1 0 0</xyz>
          <limit>
            <lower>-1e+16</lower>
            <upper>1e+16</upper>
          </limit>
          <dynamics>
            <spring_reference>0</spring_reference>
            <spring_stiffness>0</spring_stiffness>
          </dynamics>
        </axis>
      </joint>
      <link name='tempest/thruster_5'>
        <pose relative_to='tempest/thruster_5_joint'>0 0 0 0 -0 0</pose>
        <inertial>
          <pose>0 0 0 0 -0 0</pose>
          <mass>1e-05</mass>
          <inertia>
            <ixx>1e-06</ixx>
            <ixy>0</ixy>
            <ixz>0</ixz>
            <iyy>1e-06</iyy>
            <iyz>0</iyz>
            <izz>1e-06</izz>
          </inertia>
        </inertial>
        <collision name='tempest/thruster_5_collision'>
          <pose>0 0 0 3.14159 1.57079 3.14159</pose>
          <geometry>
            <cylinder>
              <length>1e-06</length>
              <radius>1e-06</radius>
            </cylinder>
          </geometry>
          <surface>
            <contact>
              <ode/>
            </contact>
            <friction>
              <ode/>
              <torsional>
                <ode/>
              </torsional>
            </friction>
            <bounce/>
          </surface>
          <max_contacts>10</max_contacts>
        </collision>
        <visual name='tempest/thruster_5_visual'>
          <pose>0 0 0 0 -0 0</pose>
          <geometry>
            <mesh>
              <scale>1 1 1</scale>
              <uri>/home/brach/osu-uwrt/riptide_software_old/src/riptide_descriptions/meshes/Propeller.dae</uri>
            </mesh>
          </geometry>
        </visual>
        <self_collide>0</self_collide>
        <enable_wind>0</enable_wind>
        <kinematic>0</kinematic>
      </link>
      <joint name='tempest/thruster_6_joint' type='revolute'>
        <pose relative_to='tempest/base_link'>-0.29 0.322 0.0794 0 -0 0.7854</pose>
        <parent>tempest/base_link</parent>
        <child>tempest/thruster_6</child>
        <axis>
          <xyz>1 0 0</xyz>
          <limit>
            <lower>-1e+16</lower>
            <upper>1e+16</upper>
          </limit>
          <dynamics>
            <spring_reference>0</spring_reference>
            <spring_stiffness>0</spring_stiffness>
          </dynamics>
        </axis>
      </joint>
      <link name='tempest/thruster_6'>
        <pose relative_to='tempest/thruster_6_joint'>0 0 0 0 -0 0</pose>
        <inertial>
          <pose>0 0 0 0 -0 0</pose>
          <mass>1e-05</mass>
          <inertia>
            <ixx>1e-06</ixx>
            <ixy>0</ixy>
            <ixz>0</ixz>
            <iyy>1e-06</iyy>
            <iyz>0</iyz>
            <izz>1e-06</izz>
          </inertia>
        </inertial>
        <collision name='tempest/thruster_6_collision'>
          <pose>0 0 0 3.14159 1.57079 3.14159</pose>
          <geometry>
            <cylinder>
              <length>1e-06</length>
              <radius>1e-06</radius>
            </cylinder>
          </geometry>
          <surface>
            <contact>
              <ode/>
            </contact>
            <friction>
              <ode/>
              <torsional>
                <ode/>
              </torsional>
            </friction>
            <bounce/>
          </surface>
          <max_contacts>10</max_contacts>
        </collision>
        <visual name='tempest/thruster_6_visual'>
          <pose>0 0 0 0 -0 0</pose>
          <geometry>
            <mesh>
              <scale>1 1 1</scale>
              <uri>/home/brach/osu-uwrt/riptide_software_old/src/riptide_descriptions/meshes/Propeller.dae</uri>
            </mesh>
          </geometry>
        </visual>
        <self_collide>0</self_collide>
        <enable_wind>0</enable_wind>
        <kinematic>0</kinematic>
      </link>
      <joint name='tempest/thruster_7_joint' type='revolute'>
        <pose relative_to='tempest/base_link'>0.346 0.322 0.0794 0 -0 2.35619</pose>
        <parent>tempest/base_link</parent>
        <child>tempest/thruster_7</child>
        <axis>
          <xyz>1 0 0</xyz>
          <limit>
            <lower>-1e+16</lower>
            <upper>1e+16</upper>
          </limit>
          <dynamics>
            <spring_reference>0</spring_reference>
            <spring_stiffness>0</spring_stiffness>
          </dynamics>
        </axis>
      </joint>
      <link name='tempest/thruster_7'>
        <pose relative_to='tempest/thruster_7_joint'>0 0 0 0 -0 0</pose>
        <inertial>
          <pose>0 0 0 0 -0 0</pose>
          <mass>1e-05</mass>
          <inertia>
            <ixx>1e-06</ixx>
            <ixy>0</ixy>
            <ixz>0</ixz>
            <iyy>1e-06</iyy>
            <iyz>0</iyz>
            <izz>1e-06</izz>
          </inertia>
        </inertial>
        <collision name='tempest/thruster_7_collision'>
          <pose>0 0 0 3.14159 1.57079 3.14159</pose>
          <geometry>
            <cylinder>
              <length>1e-06</length>
              <radius>1e-06</radius>
            </cylinder>
          </geometry>
          <surface>
            <contact>
              <ode/>
            </contact>
            <friction>
              <ode/>
              <torsional>
                <ode/>
              </torsional>
            </friction>
            <bounce/>
          </surface>
          <max_contacts>10</max_contacts>
        </collision>
        <visual name='tempest/thruster_7_visual'>
          <pose>0 0 0 0 -0 0</pose>
          <geometry>
            <mesh>
              <scale>1 1 1</scale>
              <uri>/home/brach/osu-uwrt/riptide_software_old/src/riptide_descriptions/meshes/Propeller.dae</uri>
            </mesh>
          </geometry>
        </visual>
        <self_collide>0</self_collide>
        <enable_wind>0</enable_wind>
        <kinematic>0</kinematic>
      </link>
      <joint name='tempest/pose_sensor_joint' type='revolute'>
        <pose relative_to='tempest/base_link'>0 0 0 0 -0 0</pose>
        <parent>tempest/base_link</parent>
        <child>tempest/pose_sensor_link</child>
        <axis>
          <xyz>0 0 1</xyz>
          <limit>
            <lower>0</lower>
            <upper>0</upper>
            <effort>0</effort>
            <velocity>0</velocity>
          </limit>
          <dynamics>
            <spring_reference>0</spring_reference>
            <spring_stiffness>0</spring_stiffness>
          </dynamics>
        </axis>
      </joint>
      <link name='tempest/pose_sensor_link'>
        <pose relative_to='tempest/pose_sensor_joint'>0 0 0 0 -0 0</pose>
        <inertial>
          <pose>0 0 0 0 -0 0</pose>
          <mass>1e-05</mass>
          <inertia>
            <ixx>1e-06</ixx>
            <ixy>0</ixy>
            <ixz>0</ixz>
            <iyy>1e-06</iyy>
            <iyz>0</iyz>
            <izz>1e-06</izz>
          </inertia>
        </inertial>
        <self_collide>0</self_collide>
        <enable_wind>0</enable_wind>
        <kinematic>0</kinematic>
      </link>
      <plugin name='uuv_plugin' filename='libuuv_underwater_object_ros_plugin.so'>
        <fluid_density>1000</fluid_density>
        <flow_velocity_topic>hydrodynamics/current_velocity</flow_velocity_topic>
        <debug>0</debug>
        <link name='tempest/base_link'>
          <volume>0.0321</volume>
          <center_of_buoyancy>0.0 0.0 0.009999999999999995</center_of_buoyancy>
          <hydrodynamic_model>
            <type>fossen</type>
            <added_mass>0 0 0 0 0 0 0 0 0 0 0 0 0 0 0 0 0 0 0 0 0 0 0 0 0 0 0 0 0 0 0 0 0 0 0 0</added_mass>
            <linear_damping>-17.0 -50.0 -50.0 -2.0 -4.5 -2.5</linear_damping>
            <quadratic_damping>-180.0 -460.0 -460.0 -6.0 -12.0 -12.0</quadratic_damping>
          </hydrodynamic_model>
        </link>
        <robotNamespace>/tempest/</robotNamespace>
      </plugin>
      <plugin name='libuuv_gazebo_dvl_plugin' filename='libuuv_gazebo_ros_dvl_plugin.so'>
        <robot_namespace>tempest</robot_namespace>
        <link_name>tempest/dvl_link</link_name>
        <sensor_topic>dvl</sensor_topic>
        <update_rate>8</update_rate>
        <noise_sigma>0.001</noise_sigma>
        <noise_amplitude>1</noise_amplitude>
        <enable_gazebo_messages>0</enable_gazebo_messages>
        <enable_local_ned_frame>0</enable_local_ned_frame>
        <static_reference_frame>world</static_reference_frame>
        <beam_link_name_0>tempest/dvl_sonar0_link</beam_link_name_0>
        <beam_link_name_1>tempest/dvl_sonar1_link</beam_link_name_1>
        <beam_link_name_2>tempest/dvl_sonar2_link</beam_link_name_2>
        <beam_link_name_3>tempest/dvl_sonar3_link</beam_link_name_3>
        <beam_topic_0>dvl_sonar0</beam_topic_0>
        <beam_topic_1>dvl_sonar1</beam_topic_1>
        <beam_topic_2>dvl_sonar2</beam_topic_2>
        <beam_topic_3>dvl_sonar3</beam_topic_3>
        <robotNamespace>/tempest/</robotNamespace>
      </plugin>
      <plugin name='libuuv_gazebo_subseapressure_plugin' filename='libuuv_gazebo_ros_subsea_pressure_plugin.so'>
        <robot_namespace>tempest</robot_namespace>
        <link_name>tempest/pressure_link</link_name>
        <sensor_topic>depth/pressure</sensor_topic>
        <update_rate>20</update_rate>
        <saturation>300</saturation>
        <noise_sigma>0.029419140000000003</noise_sigma>
        <noise_amplitude>1</noise_amplitude>
        <estimate_depth_on>0</estimate_depth_on>
        <standard_pressure>101.325</standard_pressure>
        <kPa_per_meter>9.80638</kPa_per_meter>
        <enable_gazebo_messages>0</enable_gazebo_messages>
        <robotNamespace>/tempest/</robotNamespace>
      </plugin>
      <plugin name='libuuv_gazebo_imu_plugin' filename='libuuv_gazebo_ros_imu_plugin.so'>
        <robot_namespace>tempest</robot_namespace>
        <link_name>tempest/imu_revolute_link</link_name>
        <sensor_topic>imu/data/sim</sensor_topic>
        <gyroscope_noise_density>0.0003394</gyroscope_noise_density>
        <gyroscope_random_walk>3.8785e-05</gyroscope_random_walk>
        <gyroscope_bias_correlation_time>1000.0</gyroscope_bias_correlation_time>
        <gyroscope_turn_on_bias_sigma>0.0087</gyroscope_turn_on_bias_sigma>
        <accelerometer_noise_density>0.004</accelerometer_noise_density>
        <accelerometer_random_walk>0.006</accelerometer_random_walk>
        <accelerometer_bias_correlation_time>300.0</accelerometer_bias_correlation_time>
        <accelerometer_turn_on_bias_sigma>0.196</accelerometer_turn_on_bias_sigma>
        <orientation_noise>0.01</orientation_noise>
        <update_rate>100</update_rate>
        <enable_gazebo_messages>0</enable_gazebo_messages>
        <enable_local_ned_frame>0</enable_local_ned_frame>
        <static_reference_frame>world</static_reference_frame>
        <robotNamespace>/tempest/</robotNamespace>
      </plugin>
      <plugin name='pose_3d_plugin' filename='libuuv_gazebo_ros_pose_gt_plugin.so'>
        <robot_namespace>tempest</robot_namespace>
        <link_name>tempest/base_link</link_name>
        <sensor_topic>pose_gt</sensor_topic>
        <static_reference_frame>world</static_reference_frame>
        <noise_sigma>0</noise_sigma>
        <noise_amplitude>0</noise_amplitude>
        <update_rate>20</update_rate>
        <enable_gazebo_messages>0</enable_gazebo_messages>
        <publish_ned_odom>0</publish_ned_odom>
        <robotNamespace>/tempest/</robotNamespace>
      </plugin>
      <plugin name='libuuv_gazebo_imu_plugin' filename='libuuv_gazebo_ros_imu_plugin.so'>
        <robot_namespace>tempest/stereo</robot_namespace>
        <link_name>tempest/stereo/imu_revolute_link</link_name>
        <sensor_topic>imu/data_raw/sim</sensor_topic>
        <gyroscope_noise_density>0.0003394</gyroscope_noise_density>
        <gyroscope_random_walk>3.8785e-05</gyroscope_random_walk>
        <gyroscope_bias_correlation_time>1000.0</gyroscope_bias_correlation_time>
        <gyroscope_turn_on_bias_sigma>0.0087</gyroscope_turn_on_bias_sigma>
        <accelerometer_noise_density>0.004</accelerometer_noise_density>
        <accelerometer_random_walk>0.006</accelerometer_random_walk>
        <accelerometer_bias_correlation_time>300.0</accelerometer_bias_correlation_time>
        <accelerometer_turn_on_bias_sigma>0.196</accelerometer_turn_on_bias_sigma>
        <orientation_noise>0.01</orientation_noise>
        <update_rate>200</update_rate>
        <enable_gazebo_messages>0</enable_gazebo_messages>
        <enable_local_ned_frame>0</enable_local_ned_frame>
        <static_reference_frame>world</static_reference_frame>
        <robotNamespace>/tempest/</robotNamespace>
      </plugin>
      <plugin name='tempest_0_thruster_model' filename='libuuv_thruster_ros_plugin.so'>
        <linkName>tempest/thruster_0</linkName>
        <jointName>tempest/thruster_0_joint</jointName>
        <thrusterID>0</thrusterID>
        <dynamics>
          <type>ZeroOrder</type>
        </dynamics>
        <conversion>
          <type>Basic</type>
          <rotorConstant>0.01</rotorConstant>
        </conversion>
        <robotNamespace>/tempest/</robotNamespace>
      </plugin>
      <plugin name='tempest_1_thruster_model' filename='libuuv_thruster_ros_plugin.so'>
        <linkName>tempest/thruster_1</linkName>
        <jointName>tempest/thruster_1_joint</jointName>
        <thrusterID>1</thrusterID>
        <dynamics>
          <type>ZeroOrder</type>
        </dynamics>
        <conversion>
          <type>Basic</type>
          <rotorConstant>0.01</rotorConstant>
        </conversion>
        <robotNamespace>/tempest/</robotNamespace>
      </plugin>
      <plugin name='tempest_2_thruster_model' filename='libuuv_thruster_ros_plugin.so'>
        <linkName>tempest/thruster_2</linkName>
        <jointName>tempest/thruster_2_joint</jointName>
        <thrusterID>2</thrusterID>
        <dynamics>
          <type>ZeroOrder</type>
        </dynamics>
        <conversion>
          <type>Basic</type>
          <rotorConstant>0.01</rotorConstant>
        </conversion>
        <robotNamespace>/tempest/</robotNamespace>
      </plugin>
      <plugin name='tempest_3_thruster_model' filename='libuuv_thruster_ros_plugin.so'>
        <linkName>tempest/thruster_3</linkName>
        <jointName>tempest/thruster_3_joint</jointName>
        <thrusterID>3</thrusterID>
        <dynamics>
          <type>ZeroOrder</type>
        </dynamics>
        <conversion>
          <type>Basic</type>
          <rotorConstant>0.01</rotorConstant>
        </conversion>
        <robotNamespace>/tempest/</robotNamespace>
      </plugin>
      <plugin name='tempest_4_thruster_model' filename='libuuv_thruster_ros_plugin.so'>
        <linkName>tempest/thruster_4</linkName>
        <jointName>tempest/thruster_4_joint</jointName>
        <thrusterID>4</thrusterID>
        <dynamics>
          <type>ZeroOrder</type>
        </dynamics>
        <conversion>
          <type>Basic</type>
          <rotorConstant>0.01</rotorConstant>
        </conversion>
        <robotNamespace>/tempest/</robotNamespace>
      </plugin>
      <plugin name='tempest_5_thruster_model' filename='libuuv_thruster_ros_plugin.so'>
        <linkName>tempest/thruster_5</linkName>
        <jointName>tempest/thruster_5_joint</jointName>
        <thrusterID>5</thrusterID>
        <dynamics>
          <type>ZeroOrder</type>
        </dynamics>
        <conversion>
          <type>Basic</type>
          <rotorConstant>0.01</rotorConstant>
        </conversion>
        <robotNamespace>/tempest/</robotNamespace>
      </plugin>
      <plugin name='tempest_6_thruster_model' filename='libuuv_thruster_ros_plugin.so'>
        <linkName>tempest/thruster_6</linkName>
        <jointName>tempest/thruster_6_joint</jointName>
        <thrusterID>6</thrusterID>
        <dynamics>
          <type>ZeroOrder</type>
        </dynamics>
        <conversion>
          <type>Basic</type>
          <rotorConstant>0.01</rotorConstant>
        </conversion>
        <robotNamespace>/tempest/</robotNamespace>
      </plugin>
      <static>0</static>
      <plugin name='tempest_7_thruster_model' filename='libuuv_thruster_ros_plugin.so'>
        <linkName>tempest/thruster_7</linkName>
        <jointName>tempest/thruster_7_joint</jointName>
        <thrusterID>7</thrusterID>
        <dynamics>
          <type>ZeroOrder</type>
        </dynamics>
        <conversion>
          <type>Basic</type>
          <rotorConstant>0.01</rotorConstant>
        </conversion>
        <robotNamespace>/tempest/</robotNamespace>
      </plugin>
      <pose>0 0 0 0 -0 0</pose>
    </model>
    <model name='gate'>
      <static>1</static>
      <link name='link'>
        <pose>0 0 0 0 -0 0</pose>
        <must_be_base_link>1</must_be_base_link>
        <collision name='collision'>
          <geometry>
            <mesh>
              <uri>model://gate/meshes/gate.dae</uri>
            </mesh>
          </geometry>
          <max_contacts>10</max_contacts>
          <surface>
            <contact>
              <ode/>
            </contact>
            <bounce/>
            <friction>
              <torsional>
                <ode/>
              </torsional>
              <ode/>
            </friction>
          </surface>
        </collision>
        <visual name='visual'>
          <cast_shadows>0</cast_shadows>
          <geometry>
            <mesh>
              <uri>model://gate/meshes/gate.dae</uri>
            </mesh>
          </geometry>
        </visual>
        <self_collide>0</self_collide>
        <enable_wind>0</enable_wind>
        <kinematic>0</kinematic>
      </link>
      <pose>3.00926 -1.0275 0 0 -0 0</pose>
    </model>
    <model name='gman_torpedo'>
      <static>1</static>
      <link name='link'>
        <pose>0 0 0 0 -0 0</pose>
        <must_be_base_link>1</must_be_base_link>
        <collision name='collision'>
          <geometry>
            <mesh>
              <uri>model://gman_torpedo/meshes/GmanTorpedoCutout.dae</uri>
            </mesh>
          </geometry>
          <max_contacts>10</max_contacts>
          <surface>
            <contact>
              <ode/>
            </contact>
            <bounce/>
            <friction>
              <torsional>
                <ode/>
              </torsional>
              <ode/>
            </friction>
          </surface>
        </collision>
        <visual name='visual'>
          <cast_shadows>0</cast_shadows>
          <geometry>
            <mesh>
              <uri>model://gman_torpedo/meshes/GmanTorpedoCutout.dae</uri>
            </mesh>
          </geometry>
        </visual>
        <self_collide>0</self_collide>
        <enable_wind>0</enable_wind>
        <kinematic>0</kinematic>
      </link>
      <pose>2.10149 2.22228 0 0 -0 0</pose>
    </model>
    <model name='pole'>
      <static>1</static>
      <link name='link'>
        <pose>0 0 0 0 -0 0</pose>
        <must_be_base_link>1</must_be_base_link>
        <collision name='collision'>
          <geometry>
            <mesh>
              <uri>model://pole/meshes/pole.dae</uri>
            </mesh>
          </geometry>
          <max_contacts>10</max_contacts>
          <surface>
            <contact>
              <ode/>
            </contact>
            <bounce/>
            <friction>
              <torsional>
                <ode/>
              </torsional>
              <ode/>
            </friction>
          </surface>
        </collision>
        <visual name='visual'>
          <cast_shadows>0</cast_shadows>
          <geometry>
            <mesh>
              <uri>model://pole/meshes/pole.dae</uri>
            </mesh>
          </geometry>
        </visual>
        <self_collide>0</self_collide>
        <enable_wind>0</enable_wind>
        <kinematic>0</kinematic>
      </link>
      <pose>5.08901 -0.029448 0 0 -0 0</pose>
    </model>
  </world>
</sdf>
